<?xml version="1.0"?>
<robot name="so100_arm">

  <!-- Base Link -->
  <link name="base_link"/>

  <!-- Shoulder pan joint -->
  <joint name="shoulder_pan_joint" type="revolute">
    <parent link="base_link"/>
    <child link="shoulder_pan_link"/>
    <origin xyz="0 0 0.05" rpy="0 0 0"/>
    <axis xyz="0 0 1"/>
    <limit lower="-3.14" upper="3.14" effort="10" velocity="1"/>
  </joint>

  <link name="shoulder_pan_link"/>

  <!-- Shoulder lift joint -->
  <joint name="shoulder_lift_joint" type="revolute">
    <parent link="shoulder_pan_link"/>
    <child link="shoulder_lift_link"/>
    <origin xyz="0 0 0.05" rpy="0 0 0"/>
    <axis xyz="0 1 0"/>
    <limit lower="-1.57" upper="1.57" effort="10" velocity="1"/>
  </joint>

  <link name="shoulder_lift_link"/>

  <!-- Elbow joint -->
  <joint name="elbow_flex_joint" type="revolute">
    <parent link="shoulder_lift_link"/>
    <child link="elbow_link"/>
    <origin xyz="0 0 0.12" rpy="0 0 0"/>
    <axis xyz="0 1 0"/>
    <limit lower="-1.57" upper="1.57" effort="10" velocity="1"/>
  </joint>

  <link name="elbow_link"/>

  <!-- Wrist flex joint -->
  <joint name="wrist_flex_joint" type="revolute">
    <parent link="elbow_link"/>
    <child link="wrist_flex_link"/>
    <origin xyz="0 0 0.10" rpy="0 0 0"/>
    <axis xyz="0 1 0"/>
    <limit lower="-1.57" upper="1.57" effort="10" velocity="1"/>
  </joint>

  <link name="wrist_flex_link"/>

  <!-- Wrist roll joint -->
  <joint name="wrist_roll_joint" type="revolute">
    <parent link="wrist_flex_link"/>
    <child link="wrist_roll_link"/>
    <origin xyz="0 0 0.05" rpy="0 0 0"/>
    <axis xyz="1 0 0"/>
    <limit lower="-3.14" upper="3.14" effort="10" velocity="1"/>
  </joint>

  <link name="wrist_roll_link"/>

  <!-- Gripper joint (optional placeholder) -->
  <joint name="gripper_joint" type="fixed">
    <parent link="wrist_roll_link"/>
    <child link="gripper_frame_link"/>
    <origin xyz="0 0 0.05" rpy="0 0 0"/>
  </joint>

  <link name="gripper_frame_link"/>

</robot>
